Running test/selenium_src/search_questions.py:
E
======================================================================
ERROR: test_search_questions (__main__.SearchQuestions)
----------------------------------------------------------------------
Traceback (most recent call last):
  File "test/selenium_src/search_questions.py", line 21, in test_search_questions
    driver.find_element_by_css_selector("input.form-control").clear()
  File "/usr/local/lib/python2.7/dist-packages/selenium/webdriver/remote/webdriver.py", line 376, in find_element_by_css_selector
    return self.find_element(by=By.CSS_SELECTOR, value=css_selector)
  File "/usr/local/lib/python2.7/dist-packages/selenium/webdriver/remote/webdriver.py", line 664, in find_element
    {'using': by, 'value': value})['value']
  File "/usr/local/lib/python2.7/dist-packages/selenium/webdriver/remote/webdriver.py", line 173, in execute
    response = self.command_executor.execute(driver_command, params)
  File "/usr/local/lib/python2.7/dist-packages/selenium/webdriver/remote/remote_connection.py", line 349, in execute
    return self._request(command_info[0], url, body=data)
  File "/usr/local/lib/python2.7/dist-packages/selenium/webdriver/remote/remote_connection.py", line 380, in _request
    resp = self._conn.getresponse()
  File "/usr/lib/python2.7/httplib.py", line 1045, in getresponse
    response.begin()
  File "/usr/lib/python2.7/httplib.py", line 409, in begin
    version, status, reason = self._read_status()
  File "/usr/lib/python2.7/httplib.py", line 373, in _read_status
    raise BadStatusLine(line)
BadStatusLine: ''

----------------------------------------------------------------------
Ran 1 test in 13.417s

FAILED (errors=1)
